Workbook
Name BRAND_EMAIL: 'Start Here'!$C$22
Name BRAND_NAME: 'Start Here'!$C$20
Name BRAND_PHONE: 'Start Here'!$C$21
Name BRAND_WEBSITE: 'Start Here'!$C$23

Sheet Start Here
B1: =IF(TRIM($C$20)="","HMO Compliance Tracker 2026",TRIM($C$20)) -> HMO Compliance Tracker 2026
B2: HMO compliance tracker for landlords and letting agents in England · Excel and Google Sheets
B3: Version 2.0 · Law as understood at October 2026 (England)
B5: START HERE: 5 STEPS
B6: 1 Add your properties | C6: Go to Properties and type one property per row (over the two SAMPLE rows). Each property name must be unique: the other sheets pick properties from this list.
B7: 2 Log your checks | C7: Go to Compliance Log. Pick a Property and a Check type, then enter the date it was last done. The tracker looks up how often it is needed, works out Next due and Days left, and colours the Status.
B8: 3 Record day-to-day safety | C8: Use Fire Safety Log for alarm, emergency-lighting and fire-door checks; Licence Conditions to work through each HMO licence condition and check room sizes; Tenancies & Renters Rights for deposits, Right to Rent, rent increases and pet requests; PRS Database Readiness to prepare for England's new landlord database.
B9: 4 Keep contractors to hand | C9: List your gas engineer, electrician and fire-alarm company on Contractors, and record certificate references and document links against each check in the Compliance Log.
B10: 5 Check the Dashboard weekly | C10: The Dashboard updates by itself: clear Reds first, then Ambers. The Reference sheet explains every check, how often it is normally needed, and the official source.
B11: To clear the SAMPLE data: on each sheet select the white input cells in the rows marked SAMPLE and press Delete. Leave the grey formula cells alone.
B13: COLOUR KEY
B14: Red: Overdue | C14: The due date has passed. Deal with these first.
B15: Amber: Due within 60 days | C15: Orange = due in 30 days or less (Due <=30). Yellow = due in 31 to 60 days (Due 31-60).
B16: Green: OK | C16: More than 60 days left.
B17: Grey: No date entered | C17: No last-done date has been entered yet, or the date is not recognised as a date.
B18: Amber is split into two shades so you can see what is most urgent.
B19: BRAND: change these 4 cells and the header line on every sheet updates (white-label copy)
B20: Business name | C20: HMO Compliance Tracker 2026 | D20: Shown at the top of every sheet.
B21: Phone | D21: Optional. Leave empty to hide.
B22: Email | D22: Optional. Leave empty to hide.
B23: Website | D23: Optional. Leave empty to hide.
B24: Header preview | C24: =IF(TRIM('Start Here'!$C$20)="","HMO Compliance Tracker 2026",TRIM('Start Here'!$C$20))&IF(TRIM('Start Here'!$C$21)="",""," | "&TRIM('Start Here'!$C$21))&IF(TRIM('Start Here'!$C$22)="",""," | "&TRIM('Start Here'!$C$22))&IF(TRIM('Start Here'!$C$23)="",""," | "&TRIM('Start Here'!$C$23)) -> HMO Compliance Tracker 2026
B26: ABOUT THIS VERSION
B27: Version | C27: 2.0 (October 2026)
B28: Law | C28: Law as understood at October 2026 (England)
B29: Coverage | C29: England only. Wales, Scotland and Northern Ireland have different rules.
B30: Support | C30: hello@innovateuk.uk
B32: IMPORTANT
B33: This tracker is an organisational tool, not legal advice. Check requirements with your local council and a qualified adviser.
B34: Independent product. Not affiliated with, endorsed by or connected to Innovate UK, UKRI, GOV.UK or any council. The Reference sheet links to the official sources used.
B36: USING GOOGLE SHEETS?
B37: Upload the .xlsx to Google Drive (or Google Sheets > File > Import > Upload) and open it with Google Sheets. Then choose File > Settings > Locale > United Kingdom so dates read dd/mm/yyyy. Everything works without add-ons or scripts.
B39: SHEETS IN THIS WORKBOOK (click to jump)
B40: Dashboard | C40: Totals, per-property summary and the next 15 deadlines. Automatic.
B41: PRS Database Readiness | C41: NEW: get every property ready for the new national landlord database (draft regulations).
B42: Properties | C42: Your properties: licence, occupancy, EPC, PRS Database reference, manager.
B43: Compliance Log | C43: One row per property and check. Next due, days left and status are automatic.
B44: Fire Safety Log | C44: Weekly alarm tests, emergency lighting, fire doors, drills and defects.
B45: Licence Conditions | C45: HMO licence condition checklists and the room-size calculator.
B46: Tenancies & Renters Rights | C46: Deposits, Right to Rent, written terms, Information Sheet, rent increases, pet requests.
...

Sheet Dashboard
A1: =IF(TRIM('Start Here'!$C$20)="","HMO Compliance Tracker 2026",TRIM('Start Here'!$C$20))&IF(TRIM('Start Here'!$C$21)="",""," | "&TRIM('Start Here'!$C$21))&IF(TRIM('Start Here'!$C$22)="",""," | "&TRIM('Start Here'!$C$22))&IF(TRIM('Start Here'!$C$23)="",""," | "&TRIM('Start Here'!$C$23)) -> HMO Compliance Tracker 2026
B2: Dashboard
B3: ="Updates automatically from the Compliance Log, Properties and Fire Safety Log. As at "&TEXT(TODAY(),"dd/mm/yyyy") -> Updates automatically from the Compliance Log, Properties and Fire Safety Log. As at 02/10/2026
B5: PROPERTIES | D5: CHECKS TRACKED | F5: OVERDUE | H5: DUE <=30 DAYS | J5: DUE 31-60 DAYS | L5: OK
B6: =COUNTA(Properties!$A$6:$A$105) -> 2 | D6: =SUMPRODUCT(--('Compliance Log'!$H$6:$H$1005<>"")) -> 15 | F6: =SUMPRODUCT(--('Compliance Log'!$H$6:$H$1005="Overdue")) -> 3 | H6: =SUMPRODUCT(--('Compliance Log'!$H$6:$H$1005="Due <=30")) -> 2 | J6: =SUMPRODUCT(--('Compliance Log'!$H$6:$H$1005="Due 31-60")) -> 3 | L6: =SUMPRODUCT(--('Compliance Log'!$H$6:$H$1005="OK")) -> 6
B8: NO DATE ENTERED | D8: OPEN FIRE-SAFETY DEFECTS | F8: LICENCES EXPIRED / <=60 DAYS | H8: PROPERTIES OVER-OCCUPIED | J8: PRS DB: NOT YET READY | L8: PRS DB: EARLIEST DEADLINE
B9: =SUMPRODUCT(--('Compliance Log'!$H$6:$H$1005="No date")) -> 1 | D9: =SUMPRODUCT(--('Fire Safety Log'!$J$6:$J$1005="OPEN")) -> 1 | F9: =SUMPRODUCT((Properties!$H$6:$H$105="Expired")+(Properties!$H$6:$H$105="Expires <=30")+(Properties!$H$6:$H$105="Expires 31-60")) -> 1 | H9: =SUMPRODUCT(--(Properties!$K$6:$K$105="OVER")) -> 1 | J9: =SUMPRODUCT(('PRS Database Readiness'!$I$9:$I$108="Nearly")+('PRS Database Readiness'!$I$9:$I$108="Not ready")) -> 2 | L9: =IF(COUNT('PRS Database Readiness'!$AJ$9:$AJ$108)=0,"n/a",MIN('PRS Database Readiness'!$AJ$9:$AJ$108)) -> 46460
B11: NEXT 15 DEADLINES (soonest first, overdue items at the top)
B12: # | C12: Due date | D12: Days left | E12: Property | H12: Check | L12: Status
B13: =IF($P13="","",ROW()-ROW($B$12)) -> 1 | C13: =IF($P13="","",INDEX('Compliance Log'!$F$6:$F$1005,$P13)) -> 45962 | D13: =IF($P13="","",INDEX('Compliance Log'!$G$6:$G$1005,$P13)) -> -335 | E13: =IF($P13="","",INDEX('Compliance Log'!$A$6:$A$1005,$P13)) -> SAMPLE - 12 Acacia Road, Exampleton | H13: =IF($P13="","",INDEX('Compliance Log'!$B$6:$B$1005,$P13)) -> Portable appliance testing (PAT) | L13: =IF($P13="","",INDEX('Compliance Log'!$H$6:$H$1005,$P13)) -> Overdue | P13: =IFERROR(MATCH(SMALL('Compliance Log'!$M$6:$M$1005,ROW()-ROW($P$12)),'Compliance Log'!$M$6:$M$1005,0),"") -> 7
B14: =IF($P14="","",ROW()-ROW($B$12)) -> 2 | C14: =IF($P14="","",INDEX('Compliance Log'!$F$6:$F$1005,$P14)) -> 46242 | D14: =IF($P14="","",INDEX('Compliance Log'!$G$6:$G$1005,$P14)) -> -55 | E14: =IF($P14="","",INDEX('Compliance Log'!$A$6:$A$1005,$P14)) -> SAMPLE - Flat 3, 8 Demo Street, Sampleford | H14: =IF($P14="","",INDEX('Compliance Log'!$B$6:$B$1005,$P14)) -> Smoke & CO alarms - check | L14: =IF($P14="","",INDEX('Compliance Log'!$H$6:$H$1005,$P14)) -> Overdue | P14: =IFERROR(MATCH(SMALL('Compliance Log'!$M$6:$M$1005,ROW()-ROW($P$12)),'Compliance Log'!$M$6:$M$1005,0),"") -> 13
B15: =IF($P15="","",ROW()-ROW($B$12)) -> 3 | C15: =IF($P15="","",INDEX('Compliance Log'!$F$6:$F$1005,$P15)) -> 46272 | D15: =IF($P15="","",INDEX('Compliance Log'!$G$6:$G$1005,$P15)) -> -25 | E15: =IF($P15="","",INDEX('Compliance Log'!$A$6:$A$1005,$P15)) -> SAMPLE - 12 Acacia Road, Exampleton | H15: =IF($P15="","",INDEX('Compliance Log'!$B$6:$B$1005,$P15)) -> Gas Safety Certificate (CP12) | L15: =IF($P15="","",INDEX('Compliance Log'!$H$6:$H$1005,$P15)) -> Overdue | P15: =IFERROR(MATCH(SMALL('Compliance Log'!$M$6:$M$1005,ROW()-ROW($P$12)),'Compliance Log'!$M$6:$M$1005,0),"") -> 1
B16: =IF($P16="","",ROW()-ROW($B$12)) -> 4 | C16: =IF($P16="","",INDEX('Compliance Log'!$F$6:$F$1005,$P16)) -> 46312 | D16: =IF($P16="","",INDEX('Compliance Log'!$G$6:$G$1005,$P16)) -> 15 | E16: =IF($P16="","",INDEX('Compliance Log'!$A$6:$A$1005,$P16)) -> SAMPLE - 12 Acacia Road, Exampleton | H16: =IF($P16="","",INDEX('Compliance Log'!$B$6:$B$1005,$P16)) -> Emergency lighting - annual full-discharge test | L16: =IF($P16="","",INDEX('Compliance Log'!$H$6:$H$1005,$P16)) -> Due <=30 | P16: =IFERROR(MATCH(SMALL('Compliance Log'!$M$6:$M$1005,ROW()-ROW($P$12)),'Compliance Log'!$M$6:$M$1005,0),"") -> 5
B17: =IF($P17="","",ROW()-ROW($B$12)) -> 5 | C17: =IF($P17="","",INDEX('Compliance Log'!$F$6:$F$1005,$P17)) -> 46317 | D17: =IF($P17="","",INDEX('Compliance Log'!$G$6:$G$1005,$P17)) -> 20 | E17: =IF($P17="","",INDEX('Compliance Log'!$A$6:$A$1005,$P17)) -> SAMPLE - Flat 3, 8 Demo Street, Sampleford | H17: =IF($P17="","",INDEX('Compliance Log'!$B$6:$B$1005,$P17)) -> Fire extinguishers - service | L17: =IF($P17="","",INDEX('Compliance Log'!$H$6:$H$1005,$P17)) -> Due <=30 | P17: =IFERROR(MATCH(SMALL('Compliance Log'!$M$6:$M$1005,ROW()-ROW($P$12)),'Compliance Log'!$M$6:$M$1005,0),"") -> 14
B18: =IF($P18="","",ROW()-ROW($B$12)) -> 6 | C18: =IF($P18="","",INDEX('Compliance Log'!$F$6:$F$1005,$P18)) -> 46333 | D18: =IF($P18="","",INDEX('Compliance Log'!$G$6:$G$1005,$P18)) -> 36 | E18: =IF($P18="","",INDEX('Compliance Log'!$A$6:$A$1005,$P18)) -> SAMPLE - Flat 3, 8 Demo Street, Sampleford | H18: =IF($P18="","",INDEX('Compliance Log'!$B$6:$B$1005,$P18)) -> Electrical Installation Condition Report (EICR) | L18: =IF($P18="","",INDEX('Compliance Log'!$H$6:$H$1005,$P18)) -> Due 31-60 | P18: =IFERROR(MATCH(SMALL('Compliance Log'!$M$6:$M$1005,ROW()-ROW($P$12)),'Compliance Log'!$M$6:$M$1005,0),"") -> 10
B19: =IF($P19="","",ROW()-ROW($B$12)) -> 7 | C19: =IF($P19="","",INDEX('Compliance Log'!$F$6:$F$1005,$P19)) -> 46337 | D19: =IF($P19="","",INDEX('Compliance Log'!$G$6:$G$1005,$P19)) -> 40 | E19: =IF($P19="","",INDEX('Compliance Log'!$A$6:$A$1005,$P19)) -> SAMPLE - Flat 3, 8 Demo Street, Sampleford | H19: =IF($P19="","",INDEX('Compliance Log'!$B$6:$B$1005,$P19)) -> HMO licence renewal | L19: =IF($P19="","",INDEX('Compliance Log'!$H$6:$H$1005,$P19)) -> Due 31-60 | P19: =IFERROR(MATCH(SMALL('Compliance Log'!$M$6:$M$1005,ROW()-ROW($P$12)),'Compliance Log'!$M$6:$M$1005,0),"") -> 15
B20: =IF($P20="","",ROW()-ROW($B$12)) -> 8 | C20: =IF($P20="","",INDEX('Compliance Log'!$F$6:$F$1005,$P20)) -> 46342 | D20: =IF($P20="","",INDEX('Compliance Log'!$G$6:$G$1005,$P20)) -> 45 | E20: =IF($P20="","",INDEX('Compliance Log'!$A$6:$A$1005,$P20)) -> SAMPLE - 12 Acacia Road, Exampleton | H20: =IF($P20="","",INDEX('Compliance Log'!$B$6:$B$1005,$P20)) -> Fire Risk Assessment - review | L20: =IF($P20="","",INDEX('Compliance Log'!$H$6:$H$1005,$P20)) -> Due 31-60 | P20: =IFERROR(MATCH(SMALL('Compliance Log'!$M$6:$M$1005,ROW()-ROW($P$12)),'Compliance Log'!$M$6:$M$1005,0),"") -> 3
B21: =IF($P21="","",ROW()-ROW($B$12)) -> 9 | C21: =IF($P21="","",INDEX('Compliance Log'!$F$6:$F$1005,$P21)) -> 46421 | D21: =IF($P21="","",INDEX('Compliance Log'!$G$6:$G$1005,$P21)) -> 124 | E21: =IF($P21="","",INDEX('Compliance Log'!$A$6:$A$1005,$P21)) -> SAMPLE - 12 Acacia Road, Exampleton | H21: =IF($P21="","",INDEX('Compliance Log'!$B$6:$B$1005,$P21)) -> Fire alarm system - service | L21: =IF($P21="","",INDEX('Compliance Log'!$H$6:$H$1005,$P21)) -> OK | P21: =IFERROR(MATCH(SMALL('Compliance Log'!$M$6:$M$1005,ROW()-ROW($P$12)),'Compliance Log'!$M$6:$M$1005,0),"") -> 4
B22: =IF($P22="","",ROW()-ROW($B$12)) -> 10 | C22: =IF($P22="","",INDEX('Compliance Log'!$F$6:$F$1005,$P22)) -> 46423 | D22: =IF($P22="","",INDEX('Compliance Log'!$G$6:$G$1005,$P22)) -> 126 | E22: =IF($P22="","",INDEX('Compliance Log'!$A$6:$A$1005,$P22)) -> SAMPLE - 12 Acacia Road, Exampleton | H22: =IF($P22="","",INDEX('Compliance Log'!$B$6:$B$1005,$P22)) -> HMO licence renewal | L22: =IF($P22="","",INDEX('Compliance Log'!$H$6:$H$1005,$P22)) -> OK | P22: =IFERROR(MATCH(SMALL('Compliance Log'!$M$6:$M$1005,ROW()-ROW($P$12)),'Compliance Log'!$M$6:$M$1005,0),"") -> 8
B23: =IF($P23="","",ROW()-ROW($B$12)) -> 11 | C23: =IF($P23="","",INDEX('Compliance Log'!$F$6:$F$1005,$P23)) -> 46542 | D23: =IF($P23="","",INDEX('Compliance Log'!$G$6:$G$1005,$P23)) -> 245 | E23: =IF($P23="","",INDEX('Compliance Log'!$A$6:$A$1005,$P23)) -> SAMPLE - Flat 3, 8 Demo Street, Sampleford | H23: =IF($P23="","",INDEX('Compliance Log'!$B$6:$B$1005,$P23)) -> Gas Safety Certificate (CP12) | L23: =IF($P23="","",INDEX('Compliance Log'!$H$6:$H$1005,$P23)) -> OK | P23: =IFERROR(MATCH(SMALL('Compliance Log'!$M$6:$M$1005,ROW()-ROW($P$12)),'Compliance Log'!$M$6:$M$1005,0),"") -> 9
B24: =IF($P24="","",ROW()-ROW($B$12)) -> 12 | C24: =IF($P24="","",INDEX('Compliance Log'!$F$6:$F$1005,$P24)) -> 46572 | D24: =IF($P24="","",INDEX('Compliance Log'!$G$6:$G$1005,$P24)) -> 275 | E24: =IF($P24="","",INDEX('Compliance Log'!$A$6:$A$1005,$P24)) -> SAMPLE - 12 Acacia Road, Exampleton | H24: =IF($P24="","",INDEX('Compliance Log'!$B$6:$B$1005,$P24)) -> Fire extinguishers - service | L24: =IF($P24="","",INDEX('Compliance Log'!$H$6:$H$1005,$P24)) -> OK | P24: =IFERROR(MATCH(SMALL('Compliance Log'!$M$6:$M$1005,ROW()-ROW($P$12)),'Compliance Log'!$M$6:$M$1005,0),"") -> 6
... B27: =IF($P27="","",ROW()-ROW($B$12)) | C27: =IF($P27="","",INDEX('Compliance Log'!$F$6:$F$1005,$P27)) | D27: =IF($P27="","",INDEX('Compliance Log'!$G$6:$G$1005,$P27)) | E27: =IF($P27="","",INDEX('Compliance Log'!$A$6:$A$1005,$P27)) | H27: =IF($P27="","",INDEX('Compliance Log'!$B$6:$B$1005,$P27)) | L27: =IF($P27="","",INDEX('Compliance Log'!$H$6:$H$1005,$P27)) | P27: =IFERROR(MATCH(SMALL('Compliance Log'!$M$6:$M$1005,ROW()-ROW($P$12)),'Compliance Log'!$M$6:$M$1005,0),"")
B29: PROPERTY SUMMARY (from the Compliance Log)
B30: Property | G30: Overdue | H30: Due soon (<=60) | I30: OK | J30: No date | K30: Worst status | M30: Checks
B31: =IF(INDEX(Properties!$A$6:$A$105,ROW()-ROW($B$30))="","",INDEX(Properties!$A$6:$A$105,ROW()-ROW($B$30))) -> SAMPLE - 12 Acacia Road, Exampleton | G31: =IF($B31="","",SUMPRODUCT(('Compliance Log'!$A$6:$A$1005=$B31)*('Compliance Log'!$H$6:$H$1005="Overdue"))) -> 2 | H31: =IF($B31="","",SUMPRODUCT(('Compliance Log'!$A$6:$A$1005=$B31)*(('Compliance Log'!$H$6:$H$1005="Due <=30")+('Compliance Log'!$H$6:$H$1005="Due 31-60")))) -> 2 | I31: =IF($B31="","",SUMPRODUCT(('Compliance Log'!$A$6:$A$1005=$B31)*('Compliance Log'!$H$6:$H$1005="OK"))) -> 4 | J31: =IF($B31="","",SUMPRODUCT(('Compliance Log'!$A$6:$A$1005=$B31)*('Compliance Log'!$H$6:$H$1005="No date"))) -> 0 | K31: =IF($B31="","",IF($G31>0,"Overdue",IF(SUMPRODUCT(('Compliance Log'!$A$6:$A$1005=$B31)*('Compliance Log'!$H$6:$H$1005="Due <=30"))>0,"Due <=30",IF($H31>0,"Due 31-60",IF($J31>0,"No date",IF($I31>0,"OK","No checks")))))) -> Overdue | M31: =IF($B31="","",$G31+$H31+$I31+$J31) -> 8
B32: =IF(INDEX(Properties!$A$6:$A$105,ROW()-ROW($B$30))="","",INDEX(Properties!$A$6:$A$105,ROW()-ROW($B$30))) -> SAMPLE - Flat 3, 8 Demo Street, Sampleford | G32: =IF($B32="","",SUMPRODUCT(('Compliance Log'!$A$6:$A$1005=$B32)*('Compliance Log'!$H$6:$H$1005="Overdue"))) -> 1 | H32: =IF($B32="","",SUMPRODUCT(('Compliance Log'!$A$6:$A$1005=$B32)*(('Compliance Log'!$H$6:$H$1005="Due <=30")+('Compliance Log'!$H$6:$H$1005="Due 31-60")))) -> 3 | I32: =IF($B32="","",SUMPRODUCT(('Compliance Log'!$A$6:$A$1005=$B32)*('Compliance Log'!$H$6:$H$1005="OK"))) -> 2 | J32: =IF($B32="","",SUMPRODUCT(('Compliance Log'!$A$6:$A$1005=$B32)*('Compliance Log'!$H$6:$H$1005="No date"))) -> 1 | K32: =IF($B32="","",IF($G32>0,"Overdue",IF(SUMPRODUCT(('Compliance Log'!$A$6:$A$1005=$B32)*('Compliance Log'!$H$6:$H$1005="Due <=30"))>0,"Due <=30",IF($H32>0,"Due 31-60",IF($J32>0,"No date",IF($I32>0,"OK","No checks")))))) -> Overdue | M32: =IF($B32="","",$G32+$H32+$I32+$J32) -> 7
B33: =IF(INDEX(Properties!$A$6:$A$105,ROW()-ROW($B$30))="","",INDEX(Properties!$A$6:$A$105,ROW()-ROW($B$30))) | G33: =IF($B33="","",SUMPRODUCT(('Compliance Log'!$A$6:$A$1005=$B33)*('Compliance Log'!$H$6:$H$1005="Overdue"))) | H33: =IF($B33="","",SUMPRODUCT(('Compliance Log'!$A$6:$A$1005=$B33)*(('Compliance Log'!$H$6:$H$1005="Due <=30")+('Compliance Log'!$H$6:$H$1005="Due 31-60")))) | I33: =IF($B33="","",SUMPRODUCT(('Compliance Log'!$A$6:$A$1005=$B33)*('Compliance Log'!$H$6:$H$1005="OK"))) | J33: =IF($B33="","",SUMPRODUCT(('Compliance Log'!$A$6:$A$1005=$B33)*('Compliance Log'!$H$6:$H$1005="No date"))) | K33: =IF($B33="","",IF($G33>0,"Overdue",IF(SUMPRODUCT(('Compliance Log'!$A$6:$A$1005=$B33)*('Compliance Log'!$H$6:$H$1005="Due <=30"))>0,"Due <=30",IF($H33>0,"Due 31-60",IF($J33>0,"No date",IF($I33>0,"OK","No checks")))))) | M33: =IF($B33="","",$G33+$H33+$I33+$J33)
B34: =IF(INDEX(Properties!$A$6:$A$105,ROW()-ROW($B$30))="","",INDEX(Properties!$A$6:$A$105,ROW()-ROW($B$30))) | G34: =IF($B34="","",SUMPRODUCT(('Compliance Log'!$A$6:$A$1005=$B34)*('Compliance Log'!$H$6:$H$1005="Overdue"))) | H34: =IF($B34="","",SUMPRODUCT(('Compliance Log'!$A$6:$A$1005=$B34)*(('Compliance Log'!$H$6:$H$1005="Due <=30")+('Compliance Log'!$H$6:$H$1005="Due 31-60")))) | I34: =IF($B34="","",SUMPRODUCT(('Compliance Log'!$A$6:$A$1005=$B34)*('Compliance Log'!$H$6:$H$1005="OK"))) | J34: =IF($B34="","",SUMPRODUCT(('Compliance Log'!$A$6:$A$1005=$B34)*('Compliance Log'!$H$6:$H$1005="No date"))) | K34: =IF($B34="","",IF($G34>0,"Overdue",IF(SUMPRODUCT(('Compliance Log'!$A$6:$A$1005=$B34)*('Compliance Log'!$H$6:$H$1005="Due <=30"))>0,"Due <=30",IF($H34>0,"Due 31-60",IF($J34>0,"No date",IF($I34>0,"OK","No checks")))))) | M34: =IF($B34="","",$G34+$H34+$I34+$J34)
B35: =IF(INDEX(Properties!$A$6:$A$105,ROW()-ROW($B$30))="","",INDEX(Properties!$A$6:$A$105,ROW()-ROW($B$30))) | G35: =IF($B35="","",SUMPRODUCT(('Compliance Log'!$A$6:$A$1005=$B35)*('Compliance Log'!$H$6:$H$1005="Overdue"))) | H35: =IF($B35="","",SUMPRODUCT(('Compliance Log'!$A$6:$A$1005=$B35)*(('Compliance Log'!$H$6:$H$1005="Due <=30")+('Compliance Log'!$H$6:$H$1005="Due 31-60")))) | I35: =IF($B35="","",SUMPRODUCT(('Compliance Log'!$A$6:$A$1005=$B35)*('Compliance Log'!$H$6:$H$1005="OK"))) | J35: =IF($B35="","",SUMPRODUCT(('Compliance Log'!$A$6:$A$1005=$B35)*('Compliance Log'!$H$6:$H$1005="No date"))) | K35: =IF($B35="","",IF($G35>0,"Overdue",IF(SUMPRODUCT(('Compliance Log'!$A$6:$A$1005=$B35)*('Compliance Log'!$H$6:$H$1005="Due <=30"))>0,"Due <=30",IF($H35>0,"Due 31-60",IF($J35>0,"No date",IF($I35>0,"OK","No checks")))))) | M35: =IF($B35="","",$G35+$H35+$I35+$J35)
B36: =IF(INDEX(Properties!$A$6:$A$105,ROW()-ROW($B$30))="","",INDEX(Properties!$A$6:$A$105,ROW()-ROW($B$30))) | G36: =IF($B36="","",SUMPRODUCT(('Compliance Log'!$A$6:$A$1005=$B36)*('Compliance Log'!$H$6:$H$1005="Overdue"))) | H36: =IF($B36="","",SUMPRODUCT(('Compliance Log'!$A$6:$A$1005=$B36)*(('Compliance Log'!$H$6:$H$1005="Due <=30")+('Compliance Log'!$H$6:$H$1005="Due 31-60")))) | I36: =IF($B36="","",SUMPRODUCT(('Compliance Log'!$A$6:$A$1005=$B36)*('Compliance Log'!$H$6:$H$1005="OK"))) | J36: =IF($B36="","",SUMPRODUCT(('Compliance Log'!$A$6:$A$1005=$B36)*('Compliance Log'!$H$6:$H$1005="No date"))) | K36: =IF($B36="","",IF($G36>0,"Overdue",IF(SUMPRODUCT(('Compliance Log'!$A$6:$A$1005=$B36)*('Compliance Log'!$H$6:$H$1005="Due <=30"))>0,"Due <=30",IF($H36>0,"Due 31-60",IF($J36>0,"No date",IF($I36>0,"OK","No checks")))))) | M36: =IF($B36="","",$G36+$H36+$I36+$J36)
B37: =IF(INDEX(Properties!$A$6:$A$105,ROW()-ROW($B$30))="","",INDEX(Properties!$A$6:$A$105,ROW()-ROW($B$30))) | G37: =IF($B37="","",SUMPRODUCT(('Compliance Log'!$A$6:$A$1005=$B37)*('Compliance Log'!$H$6:$H$1005="Overdue"))) | H37: =IF($B37="","",SUMPRODUCT(('Compliance Log'!$A$6:$A$1005=$B37)*(('Compliance Log'!$H$6:$H$1005="Due <=30")+('Compliance Log'!$H$6:$H$1005="Due 31-60")))) | I37: =IF($B37="","",SUMPRODUCT(('Compliance Log'!$A$6:$A$1005=$B37)*('Compliance Log'!$H$6:$H$1005="OK"))) | J37: =IF($B37="","",SUMPRODUCT(('Compliance Log'!$A$6:$A$1005=$B37)*('Compliance Log'!$H$6:$H$1005="No date"))) | K37: =IF($B37="","",IF($G37>0,"Overdue",IF(SUMPRODUCT(('Compliance Log'!$A$6:$A$1005=$B37)*('Compliance Log'!$H$6:$H$1005="Due <=30"))>0,"Due <=30",IF($H37>0,"Due 31-60",IF($J37>0,"No date",IF($I37>0,"OK","No checks")))))) | M37: =IF($B37="","",$G37+$H37+$I37+$J37)
B38: =IF(INDEX(Properties!$A$6:$A$105,ROW()-ROW($B$30))="","",INDEX(Properties!$A$6:$A$105,ROW()-ROW($B$30))) | G38: =IF($B38="","",SUMPRODUCT(('Compliance Log'!$A$6:$A$1005=$B38)*('Compliance Log'!$H$6:$H$1005="Overdue"))) | H38: =IF($B38="","",SUMPRODUCT(('Compliance Log'!$A$6:$A$1005=$B38)*(('Compliance Log'!$H$6:$H$1005="Due <=30")+('Compliance Log'!$H$6:$H$1005="Due 31-60")))) | I38: =IF($B38="","",SUMPRODUCT(('Compliance Log'!$A$6:$A$1005=$B38)*('Compliance Log'!$H$6:$H$1005="OK"))) | J38: =IF($B38="","",SUMPRODUCT(('Compliance Log'!$A$6:$A$1005=$B38)*('Compliance Log'!$H$6:$H$1005="No date"))) | K38: =IF($B38="","",IF($G38>0,"Overdue",IF(SUMPRODUCT(('Compliance Log'!$A$6:$A$1005=$B38)*('Compliance Log'!$H$6:$H$1005="Due <=30"))>0,"Due <=30",IF($H38>0,"Due 31-60",IF($J38>0,"No date",IF($I38>0,"OK","No checks")))))) | M38: =IF($B38="","",$G38+$H38+$I38+$J38)
B39: =IF(INDEX(Properties!$A$6:$A$105,ROW()-ROW($B$30))="","",INDEX(Properties!$A$6:$A$105,ROW()-ROW($B$30))) | G39: =IF($B39="","",SUMPRODUCT(('Compliance Log'!$A$6:$A$1005=$B39)*('Compliance Log'!$H$6:$H$1005="Overdue"))) | H39: =IF($B39="","",SUMPRODUCT(('Compliance Log'!$A$6:$A$1005=$B39)*(('Compliance Log'!$H$6:$H$1005="Due <=30")+('Compliance Log'!$H$6:$H$1005="Due 31-60")))) | I39: =IF($B39="","",SUMPRODUCT(('Compliance Log'!$A$6:$A$1005=$B39)*('Compliance Log'!$H$6:$H$1005="OK"))) | J39: =IF($B39="","",SUMPRODUCT(('Compliance Log'!$A$6:$A$1005=$B39)*('Compliance Log'!$H$6:$H$1005="No date"))) | K39: =IF($B39="","",IF($G39>0,"Overdue",IF(SUMPRODUCT(('Compliance Log'!$A$6:$A$1005=$B39)*('Compliance Log'!$H$6:$H$1005="Due <=30"))>0,"Due <=30",IF($H39>0,"Due 31-60",IF($J39>0,"No date",IF($I39>0,"OK","No checks")))))) | M39: =IF($B39="","",$G39+$H39+$I39+$J39)
B40: =IF(INDEX(Properties!$A$6:$A$105,ROW()-ROW($B$30))="","",INDEX(Properties!$A$6:$A$105,ROW()-ROW($B$30))) | G40: =IF($B40="","",SUMPRODUCT(('Compliance Log'!$A$6:$A$1005=$B40)*('Compliance Log'!$H$6:$H$1005="Overdue"))) | H40: =IF($B40="","",SUMPRODUCT(('Compliance Log'!$A$6:$A$1005=$B40)*(('Compliance Log'!$H$6:$H$1005="Due <=30")+('Compliance Log'!$H$6:$H$1005="Due 31-60")))) | I40: =IF($B40="","",SUMPRODUCT(('Compliance Log'!$A$6:$A$1005=$B40)*('Compliance Log'!$H$6:$H$1005="OK"))) | J40: =IF($B40="","",SUMPRODUCT(('Compliance Log'!$A$6:$A$1005=$B40)*('Compliance Log'!$H$6:$H$1005="No date"))) | K40: =IF($B40="","",IF($G40>0,"Overdue",IF(SUMPRODUCT(('Compliance Log'!$A$6:$A$1005=$B40)*('Compliance Log'!$H$6:$H$1005="Due <=30"))>0,"Due <=30",IF($H40>0,"Due 31-60",IF($J40>0,"No date",IF($I40>0,"OK","No checks")))))) | M40: =IF($B40="","",$G40+$H40+$I40+$J40)
B41: =IF(INDEX(Properties!$A$6:$A$105,ROW()-ROW($B$30))="","",INDEX(Properties!$A$6:$A$105,ROW()-ROW($B$30))) | G41: =IF($B41="","",SUMPRODUCT(('Compliance Log'!$A$6:$A$1005=$B41)*('Compliance Log'!$H$6:$H$1005="Overdue"))) | H41: =IF($B41="","",SUMPRODUCT(('Compliance Log'!$A$6:$A$1005=$B41)*(('Compliance Log'!$H$6:$H$1005="Due <=30")+('Compliance Log'!$H$6:$H$1005="Due 31-60")))) | I41: =IF($B41="","",SUMPRODUCT(('Compliance Log'!$A$6:$A$1005=$B41)*('Compliance Log'!$H$6:$H$1005="OK"))) | J41: =IF($B41="","",SUMPRODUCT(('Compliance Log'!$A$6:$A$1005=$B41)*('Compliance Log'!$H$6:$H$1005="No date"))) | K41: =IF($B41="","",IF($G41>0,"Overdue",IF(SUMPRODUCT(('Compliance Log'!$A$6:$A$1005=$B41)*('Compliance Log'!$H$6:$H$1005="Due <=30"))>0,"Due <=30",IF($H41>0,"Due 31-60",IF($J41>0,"No date",IF($I41>0,"OK","No checks")))))) | M41: =IF($B41="","",$G41+$H41+$I41+$J41)
B42: =IF(INDEX(Properties!$A$6:$A$105,ROW()-ROW($B$30))="","",INDEX(Properties!$A$6:$A$105,ROW()-ROW($B$30))) | G42: =IF($B42="","",SUMPRODUCT(('Compliance Log'!$A$6:$A$1005=$B42)*('Compliance Log'!$H$6:$H$1005="Overdue"))) | H42: =IF($B42="","",SUMPRODUCT(('Compliance Log'!$A$6:$A$1005=$B42)*(('Compliance Log'!$H$6:$H$1005="Due <=30")+('Compliance Log'!$H$6:$H$1005="Due 31-60")))) | I42: =IF($B42="","",SUMPRODUCT(('Compliance Log'!$A$6:$A$1005=$B42)*('Compliance Log'!$H$6:$H$1005="OK"))) | J42: =IF($B42="","",SUMPRODUCT(('Compliance Log'!$A$6:$A$1005=$B42)*('Compliance Log'!$H$6:$H$1005="No date"))) | K42: =IF($B42="","",IF($G42>0,"Overdue",IF(SUMPRODUCT(('Compliance Log'!$A$6:$A$1005=$B42)*('Compliance Log'!$H$6:$H$1005="Due <=30"))>0,"Due <=30",IF($H42>0,"Due 31-60",IF($J42>0,"No date",IF($I42>0,"OK","No checks")))))) | M42: =IF($B42="","",$G42+$H42+$I42+$J42)
... B130: =IF(INDEX(Properties!$A$6:$A$105,ROW()-ROW($B$30))="","",INDEX(Properties!$A$6:$A$105,ROW()-ROW($B$30))) | G130: =IF($B130="","",SUMPRODUCT(('Compliance Log'!$A$6:$A$1005=$B130)*('Compliance Log'!$H$6:$H$1005="Overdue"))) | H130: =IF($B130="","",SUMPRODUCT(('Compliance Log'!$A$6:$A$1005=$B130)*(('Compliance Log'!$H$6:$H$1005="Due <=30")+('Compliance Log'!$H$6:$H$1005="Due 31-60")))) | I130: =IF($B130="","",SUMPRODUCT(('Compliance Log'!$A$6:$A$1005=$B130)*('Compliance Log'!$H$6:$H$1005="OK"))) | J130: =IF($B130="","",SUMPRODUCT(('Compliance Log'!$A$6:$A$1005=$B130)*('Compliance Log'!$H$6:$H$1005="No date"))) | K130: =IF($B130="","",IF($G130>0,"Overdue",IF(SUMPRODUCT(('Compliance Log'!$A$6:$A$1005=$B130)*('Compliance Log'!$H$6:$H$1005="Due <=30"))>0,"Due <=30",IF($H130>0,"Due 31-60",IF($J130>0,"No date",IF($I130>0,"OK","No checks")))))) | M130: =IF($B130="","",$G130+$H130+$I130+$J130)

Sheet PRS Database Readiness
A1: =IF(TRIM('Start Here'!$C$20)="","HMO Compliance Tracker 2026",TRIM('Start Here'!$C$20))&IF(TRIM('Start Here'!$C$21)="",""," | "&TRIM('Start Here'!$C$21))&IF(TRIM('Start Here'!$C$22)="",""," | "&TRIM('Start Here'!$C$22))&IF(TRIM('Start Here'!$C$23)="",""," | "&TRIM('Start Here'!$C$23)) -> HMO Compliance Tracker 2026
A2: PRS Database Readiness | F2: Regional dates and the landlord checklist are below the table (click)
A3: DRAFT REGULATIONS, NOT YET MADE. The Private Rented Sector Database Regulations 2026 were published as a draft statutory instrument in September 2026 and are subject to approval by Parliament, so dates, fees and data items may still change. This sheet follows the draft (legislation.gov.uk) and the GOV.UK announcement of 9 September 2026. Check GOV.UK before relying on it.
A4: PROPERTIES TRACKED | B4: READY | D4: NEARLY READY | F4: NOT READY | H4: REGISTERED | J4: EARLIEST REGISTER-BY DATE
A5: =COUNTA($A$9:$A$108) -> 2 | B5: =SUMPRODUCT(--($I$9:$I$108="Ready")) -> 0 | D5: =SUMPRODUCT(--($I$9:$I$108="Nearly")) -> 1 | F5: =SUMPRODUCT(--($I$9:$I$108="Not ready")) -> 1 | H5: =SUMPRODUCT(--($I$9:$I$108="Registered")) -> 0 | J5: =IF(COUNT($AJ$9:$AJ$108)=0,"n/a",MIN($AJ$9:$AJ$108)) -> 46460
A6: Fee per property per year (editable): | B6: 65 | C6: Estimated annual fee: | F6: =COUNTA($A$9:$A$108)*$B$6 -> 130 | H6: NRLA (not official) states £65 per property per year; the draft regulations leave the amount to the database operator (reg 14).
A7: READINESS (automatic): Ready = all 17 items done; Nearly = 3 or fewer left; Not ready = 4 or more left | K7: DRAFT SCHEDULE 3, PART 1: DWELLING INFORMATION | R7: DRAFT SCHEDULE 3, PART 2: TENANCY AND HEALTH AND SAFETY (may follow within 28 days of the entry if let; use Yes / No / N/A) | AD7: REGISTRATION AND UPDATES
A8: Property | B8: Region (pick from list) | C8: Registration opens (auto) | D8: Register by (auto) | E8: Days left (auto) | F8: Items ready (of 17) | G8: Items outstanding | H8: Ready % | I8: Status (auto) | J8: Registration status (auto) | K8: 1 Address of dwelling | L8: 2 Landlord name, correspondence address (no PO box), email | M8: 3 Ownership type | N8: 4 Dwelling type | O8: 5 Number of bedrooms | P8: 6 Whether currently let | Q8: 7 Name and email: freehold owner, superior landlord, property manager | R8: 8 Number of occupants | S8: 9 Number of households | T8: 10 HMO / additional / selective licence needed? Licence number(s) | U8: 11 Gas safety record copy (if gas supply) | V8: 11 Gas record issue date | W8: 12 EICR or EIC copy | X8: 12 EICR expiry date (or EIC issue date) | Y8: 13 EPC needed for current tenant? Copy of latest EPC | Z8: 14 If EPC no longer valid: current tenancy start date | AA8: 15 Registered MEES exemption (if EPC below minimum) | AB8: 16 Rent charged, frequency, utilities included? | AC8: 17 Furnished, part furnished or unfurnished | AD8: Registered on | AE8: Database reference | AF8: Next annual renewal (auto: 12 months) | AG8: Last change to registered information | AH8: Update database by (auto: 28-day period) | AI8: Notes
A9: SAMPLE - 12 Acacia Road, Exampleton | B9: West Midlands | C9: =IF($B9="","",IFERROR(VLOOKUP($B9,$A$112:$C$120,2,FALSE),"")) -> 46371 | D9: =IF($B9="","",IFERROR(VLOOKUP($B9,$A$112:$C$120,3,FALSE),"")) -> 46460 | E9: =IF(OR($D9="",ISNUMBER($AD9)),"",$D9-TODAY()) -> 163 | F9: =IF($A9="","",COUNTIF($K9:$T9,"Yes")+COUNTIF($K9:$T9,"N/A")+IF(OR($U9="N/A",AND($U9="Yes",ISNUMBER($V9))),1,0)+IF(OR($W9="N/A",AND($W9="Yes",ISNUMBER($X9))),1,0)+COUNTIF($Y9:$AC9,"Yes")+COUNTIF($Y9:$AC9,"N/A")) -> 15 | G9: =IF($A9="","",17-$F9) -> 2 | H9: =IF($A9="","",$F9/17) -> 0.88235294 | I9: =IF($A9="","",IF(ISNUMBER($AD9),"Registered",IF($G9=0,"Ready",IF($G9<=3,"Nearly","Not ready")))) -> Nearly | J9: =IF($A9="","",IF(ISNUMBER($AD9),"Registered",IF($D9="","Pick a region",IF(TODAY()>$D9,"OVERDUE: register now",IF(TODAY()>=$C9,"Open: register by "&TEXT($D9,"dd/mm/yyyy"),"Opens "&TEXT($C9,"dd/mm/yyyy")))))) -> Opens 15/12/2026 | K9: Yes | L9: Yes | M9: Yes | N9: Yes | O9: Yes | P9: Yes | Q9: Yes | R9: Yes | S9: Yes | T9: Yes | U9: Yes | V9: =TODAY()-(45) -> 46252 | W9: Yes | X9: =TODAY()+(300) -> 46597 | Y9: Yes | Z9: N/A | AA9: N/A | AB9: No | AC9: No | AF9: =IF(ISNUMBER($AD9),EDATE($AD9,12)-1,"") | AH9: =IF(ISNUMBER($AG9),$AG9+27,"") | AI9: SAMPLE ROW: two items outstanding, so 'Nearly' | AJ9: =IF(AND($A9<>"",ISNUMBER($D9),NOT(ISNUMBER($AD9))),$D9,"") -> 46460
A10: SAMPLE - Flat 3, 8 Demo Street, Sampleford | B10: North West | C10: =IF($B10="","",IFERROR(VLOOKUP($B10,$A$112:$C$120,2,FALSE),"")) -> 46522 | D10: =IF($B10="","",IFERROR(VLOOKUP($B10,$A$112:$C$120,3,FALSE),"")) -> 46613 | E10: =IF(OR($D10="",ISNUMBER($AD10)),"",$D10-TODAY()) -> 316 | F10: =IF($A10="","",COUNTIF($K10:$T10,"Yes")+COUNTIF($K10:$T10,"N/A")+IF(OR($U10="N/A",AND($U10="Yes",ISNUMBER($V10))),1,0)+IF(OR($W10="N/A",AND($W10="Yes",ISNUMBER($X10))),1,0)+COUNTIF($Y10:$AC10,"Yes")+COUNTIF($Y10:$AC10,"N/A")) -> 12 | G10: =IF($A10="","",17-$F10) -> 5 | H10: =IF($A10="","",$F10/17) -> 0.70588235 | I10: =IF($A10="","",IF(ISNUMBER($AD10),"Registered",IF($G10=0,"Ready",IF($G10<=3,"Nearly","Not ready")))) -> Not ready | J10: =IF($A10="","",IF(ISNUMBER($AD10),"Registered",IF($D10="","Pick a region",IF(TODAY()>$D10,"OVERDUE: register now",IF(TODAY()>=$C10,"Open: register by "&TEXT($D10,"dd/mm/yyyy"),"Opens "&TEXT($C10,"dd/mm/yyyy")))))) -> Opens 15/05/2027 | K10: Yes | L10: Yes | M10: Yes | N10: Yes | O10: Yes | P10: Yes | Q10: No | R10: Yes | S10: Yes | T10: No | U10: Yes | W10: No | Y10: Yes | Z10: N/A | AA10: N/A | AB10: No | AC10: Yes | AF10: =IF(ISNUMBER($AD10),EDATE($AD10,12)-1,"") | AH10: =IF(ISNUMBER($AG10),$AG10+27,"") | AI10: SAMPLE ROW: several items outstanding, so 'Not ready' | AJ10: =IF(AND($A10<>"",ISNUMBER($D10),NOT(ISNUMBER($AD10))),$D10,"") -> 46613
C11: =IF($B11="","",IFERROR(VLOOKUP($B11,$A$112:$C$120,2,FALSE),"")) | D11: =IF($B11="","",IFERROR(VLOOKUP($B11,$A$112:$C$120,3,FALSE),"")) | E11: =IF(OR($D11="",ISNUMBER($AD11)),"",$D11-TODAY()) | F11: =IF($A11="","",COUNTIF($K11:$T11,"Yes")+COUNTIF($K11:$T11,"N/A")+IF(OR($U11="N/A",AND($U11="Yes",ISNUMBER($V11))),1,0)+IF(OR($W11="N/A",AND($W11="Yes",ISNUMBER($X11))),1,0)+COUNTIF($Y11:$AC11,"Yes")+COUNTIF($Y11:$AC11,"N/A")) | G11: =IF($A11="","",17-$F11) | H11: =IF($A11="","",$F11/17) | I11: =IF($A11="","",IF(ISNUMBER($AD11),"Registered",IF($G11=0,"Ready",IF($G11<=3,"Nearly","Not ready")))) | J11: =IF($A11="","",IF(ISNUMBER($AD11),"Registered",IF($D11="","Pick a region",IF(TODAY()>$D11,"OVERDUE: register now",IF(TODAY()>=$C11,"Open: register by "&TEXT($D11,"dd/mm/yyyy"),"Opens "&TEXT($C11,"dd/mm/yyyy")))))) | AF11: =IF(ISNUMBER($AD11),EDATE($AD11,12)-1,"") | AH11: =IF(ISNUMBER($AG11),$AG11+27,"") | AJ11: =IF(AND($A11<>"",ISNUMBER($D11),NOT(ISNUMBER($AD11))),$D11,"")
C12: =IF($B12="","",IFERROR(VLOOKUP($B12,$A$112:$C$120,2,FALSE),"")) | D12: =IF($B12="","",IFERROR(VLOOKUP($B12,$A$112:$C$120,3,FALSE),"")) | E12: =IF(OR($D12="",ISNUMBER($AD12)),"",$D12-TODAY()) | F12: =IF($A12="","",COUNTIF($K12:$T12,"Yes")+COUNTIF($K12:$T12,"N/A")+IF(OR($U12="N/A",AND($U12="Yes",ISNUMBER($V12))),1,0)+IF(OR($W12="N/A",AND($W12="Yes",ISNUMBER($X12))),1,0)+COUNTIF($Y12:$AC12,"Yes")+COUNTIF($Y12:$AC12,"N/A")) | G12: =IF($A12="","",17-$F12) | H12: =IF($A12="","",$F12/17) | I12: =IF($A12="","",IF(ISNUMBER($AD12),"Registered",IF($G12=0,"Ready",IF($G12<=3,"Nearly","Not ready")))) | J12: =IF($A12="","",IF(ISNUMBER($AD12),"Registered",IF($D12="","Pick a region",IF(TODAY()>$D12,"OVERDUE: register now",IF(TODAY()>=$C12,"Open: register by "&TEXT($D12,"dd/mm/yyyy"),"Opens "&TEXT($C12,"dd/mm/yyyy")))))) | AF12: =IF(ISNUMBER($AD12),EDATE($AD12,12)-1,"") | AH12: =IF(ISNUMBER($AG12),$AG12+27,"") | AJ12: =IF(AND($A12<>"",ISNUMBER($D12),NOT(ISNUMBER($AD12))),$D12,"")
C13: =IF($B13="","",IFERROR(VLOOKUP($B13,$A$112:$C$120,2,FALSE),"")) | D13: =IF($B13="","",IFERROR(VLOOKUP($B13,$A$112:$C$120,3,FALSE),"")) | E13: =IF(OR($D13="",ISNUMBER($AD13)),"",$D13-TODAY()) | F13: =IF($A13="","",COUNTIF($K13:$T13,"Yes")+COUNTIF($K13:$T13,"N/A")+IF(OR($U13="N/A",AND($U13="Yes",ISNUMBER($V13))),1,0)+IF(OR($W13="N/A",AND($W13="Yes",ISNUMBER($X13))),1,0)+COUNTIF($Y13:$AC13,"Yes")+COUNTIF($Y13:$AC13,"N/A")) | G13: =IF($A13="","",17-$F13) | H13: =IF($A13="","",$F13/17) | I13: =IF($A13="","",IF(ISNUMBER($AD13),"Registered",IF($G13=0,"Ready",IF($G13<=3,"Nearly","Not ready")))) | J13: =IF($A13="","",IF(ISNUMBER($AD13),"Registered",IF($D13="","Pick a region",IF(TODAY()>$D13,"OVERDUE: register now",IF(TODAY()>=$C13,"Open: register by "&TEXT($D13,"dd/mm/yyyy"),"Opens "&TEXT($C13,"dd/mm/yyyy")))))) | AF13: =IF(ISNUMBER($AD13),EDATE($AD13,12)-1,"") | AH13: =IF(ISNUMBER($AG13),$AG13+27,"") | AJ13: =IF(AND($A13<>"",ISNUMBER($D13),NOT(ISNUMBER($AD13))),$D13,"")
C14: =IF($B14="","",IFERROR(VLOOKUP($B14,$A$112:$C$120,2,FALSE),"")) | D14: =IF($B14="","",IFERROR(VLOOKUP($B14,$A$112:$C$120,3,FALSE),"")) | E14: =IF(OR($D14="",ISNUMBER($AD14)),"",$D14-TODAY()) | F14: =IF($A14="","",COUNTIF($K14:$T14,"Yes")+COUNTIF($K14:$T14,"N/A")+IF(OR($U14="N/A",AND($U14="Yes",ISNUMBER($V14))),1,0)+IF(OR($W14="N/A",AND($W14="Yes",ISNUMBER($X14))),1,0)+COUNTIF($Y14:$AC14,"Yes")+COUNTIF($Y14:$AC14,"N/A")) | G14: =IF($A14="","",17-$F14) | H14: =IF($A14="","",$F14/17) | I14: =IF($A14="","",IF(ISNUMBER($AD14),"Registered",IF($G14=0,"Ready",IF($G14<=3,"Nearly","Not ready")))) | J14: =IF($A14="","",IF(ISNUMBER($AD14),"Registered",IF($D14="","Pick a region",IF(TODAY()>$D14,"OVERDUE: register now",IF(TODAY()>=$C14,"Open: register by "&TEXT($D14,"dd/mm/yyyy"),"Opens "&TEXT($C14,"dd/mm/yyyy")))))) | AF14: =IF(ISNUMBER($AD14),EDATE($AD14,12)-1,"") | AH14: =IF(ISNUMBER($AG14),$AG14+27,"") | AJ14: =IF(AND($A14<>"",ISNUMBER($D14),NOT(ISNUMBER($AD14))),$D14,"")
C15: =IF($B15="","",IFERROR(VLOOKUP($B15,$A$112:$C$120,2,FALSE),"")) | D15: =IF($B15="","",IFERROR(VLOOKUP($B15,$A$112:$C$120,3,FALSE),"")) | E15: =IF(OR($D15="",ISNUMBER($AD15)),"",$D15-TODAY()) | F15: =IF($A15="","",COUNTIF($K15:$T15,"Yes")+COUNTIF($K15:$T15,"N/A")+IF(OR($U15="N/A",AND($U15="Yes",ISNUMBER($V15))),1,0)+IF(OR($W15="N/A",AND($W15="Yes",ISNUMBER($X15))),1,0)+COUNTIF($Y15:$AC15,"Yes")+COUNTIF($Y15:$AC15,"N/A")) | G15: =IF($A15="","",17-$F15) | H15: =IF($A15="","",$F15/17) | I15: =IF($A15="","",IF(ISNUMBER($AD15),"Registered",IF($G15=0,"Ready",IF($G15<=3,"Nearly","Not ready")))) | J15: =IF($A15="","",IF(ISNUMBER($AD15),"Registered",IF($D15="","Pick a region",IF(TODAY()>$D15,"OVERDUE: register now",IF(TODAY()>=$C15,"Open: register by "&TEXT($D15,"dd/mm/yyyy"),"Opens "&TEXT($C15,"dd/mm/yyyy")))))) | AF15: =IF(ISNUMBER($AD15),EDATE($AD15,12)-1,"") | AH15: =IF(ISNUMBER($AG15),$AG15+27,"") | AJ15: =IF(AND($A15<>"",ISNUMBER($D15),NOT(ISNUMBER($AD15))),$D15,"")
C16: =IF($B16="","",IFERROR(VLOOKUP($B16,$A$112:$C$120,2,FALSE),"")) | D16: =IF($B16="","",IFERROR(VLOOKUP($B16,$A$112:$C$120,3,FALSE),"")) | E16: =IF(OR($D16="",ISNUMBER($AD16)),"",$D16-TODAY()) | F16: =IF($A16="","",COUNTIF($K16:$T16,"Yes")+COUNTIF($K16:$T16,"N/A")+IF(OR($U16="N/A",AND($U16="Yes",ISNUMBER($V16))),1,0)+IF(OR($W16="N/A",AND($W16="Yes",ISNUMBER($X16))),1,0)+COUNTIF($Y16:$AC16,"Yes")+COUNTIF($Y16:$AC16,"N/A")) | G16: =IF($A16="","",17-$F16) | H16: =IF($A16="","",$F16/17) | I16: =IF($A16="","",IF(ISNUMBER($AD16),"Registered",IF($G16=0,"Ready",IF($G16<=3,"Nearly","Not ready")))) | J16: =IF($A16="","",IF(ISNUMBER($AD16),"Registered",IF($D16="","Pick a region",IF(TODAY()>$D16,"OVERDUE: register now",IF(TODAY()>=$C16,"Open: register by "&TEXT($D16,"dd/mm/yyyy"),"Opens "&TEXT($C16,"dd/mm/yyyy")))))) | AF16: =IF(ISNUMBER($AD16),EDATE($AD16,12)-1,"") | AH16: =IF(ISNUMBER($AG16),$AG16+27,"") | AJ16: =IF(AND($A16<>"",ISNUMBER($D16),NOT(ISNUMBER($AD16))),$D16,"")
C17: =IF($B17="","",IFERROR(VLOOKUP($B17,$A$112:$C$120,2,FALSE),"")) | D17: =IF($B17="","",IFERROR(VLOOKUP($B17,$A$112:$C$120,3,FALSE),"")) | E17: =IF(OR($D17="",ISNUMBER($AD17)),"",$D17-TODAY()) | F17: =IF($A17="","",COUNTIF($K17:$T17,"Yes")+COUNTIF($K17:$T17,"N/A")+IF(OR($U17="N/A",AND($U17="Yes",ISNUMBER($V17))),1,0)+IF(OR($W17="N/A",AND($W17="Yes",ISNUMBER($X17))),1,0)+COUNTIF($Y17:$AC17,"Yes")+COUNTIF($Y17:$AC17,"N/A")) | G17: =IF($A17="","",17-$F17) | H17: =IF($A17="","",$F17/17) | I17: =IF($A17="","",IF(ISNUMBER($AD17),"Registered",IF($G17=0,"Ready",IF($G17<=3,"Nearly","Not ready")))) | J17: =IF($A17="","",IF(ISNUMBER($AD17),"Registered",IF($D17="","Pick a region",IF(TODAY()>$D17,"OVERDUE: register now",IF(TODAY()>=$C17,"Open: register by "&TEXT($D17,"dd/mm/yyyy"),"Opens "&TEXT($C17,"dd/mm/yyyy")))))) | AF17: =IF(ISNUMBER($AD17),EDATE($AD17,12)-1,"") | AH17: =IF(ISNUMBER($AG17),$AG17+27,"") | AJ17: =IF(AND($A17<>"",ISNUMBER($D17),NOT(ISNUMBER($AD17))),$D17,"")
C18: =IF($B18="","",IFERROR(VLOOKUP($B18,$A$112:$C$120,2,FALSE),"")) | D18: =IF($B18="","",IFERROR(VLOOKUP($B18,$A$112:$C$120,3,FALSE),"")) | E18: =IF(OR($D18="",ISNUMBER($AD18)),"",$D18-TODAY()) | F18: =IF($A18="","",COUNTIF($K18:$T18,"Yes")+COUNTIF($K18:$T18,"N/A")+IF(OR($U18="N/A",AND($U18="Yes",ISNUMBER($V18))),1,0)+IF(OR($W18="N/A",AND($W18="Yes",ISNUMBER($X18))),1,0)+COUNTIF($Y18:$AC18,"Yes")+COUNTIF($Y18:$AC18,"N/A")) | G18: =IF($A18="","",17-$F18) | H18: =IF($A18="","",$F18/17) | I18: =IF($A18="","",IF(ISNUMBER($AD18),"Registered",IF($G18=0,"Ready",IF($G18<=3,"Nearly","Not ready")))) | J18: =IF($A18="","",IF(ISNUMBER($AD18),"Registered",IF($D18="","Pick a region",IF(TODAY()>$D18,"OVERDUE: register now",IF(TODAY()>=$C18,"Open: register by "&TEXT($D18,"dd/mm/yyyy"),"Opens "&TEXT($C18,"dd/mm/yyyy")))))) | AF18: =IF(ISNUMBER($AD18),EDATE($AD18,12)-1,"") | AH18: =IF(ISNUMBER($AG18),$AG18+27,"") | AJ18: =IF(AND($A18<>"",ISNUMBER($D18),NOT(ISNUMBER($AD18))),$D18,"")
C19: =IF($B19="","",IFERROR(VLOOKUP($B19,$A$112:$C$120,2,FALSE),"")) | D19: =IF($B19="","",IFERROR(VLOOKUP($B19,$A$112:$C$120,3,FALSE),"")) | E19: =IF(OR($D19="",ISNUMBER($AD19)),"",$D19-TODAY()) | F19: =IF($A19="","",COUNTIF($K19:$T19,"Yes")+COUNTIF($K19:$T19,"N/A")+IF(OR($U19="N/A",AND($U19="Yes",ISNUMBER($V19))),1,0)+IF(OR($W19="N/A",AND($W19="Yes",ISNUMBER($X19))),1,0)+COUNTIF($Y19:$AC19,"Yes")+COUNTIF($Y19:$AC19,"N/A")) | G19: =IF($A19="","",17-$F19) | H19: =IF($A19="","",$F19/17) | I19: =IF($A19="","",IF(ISNUMBER($AD19),"Registered",IF($G19=0,"Ready",IF($G19<=3,"Nearly","Not ready")))) | J19: =IF($A19="","",IF(ISNUMBER($AD19),"Registered",IF($D19="","Pick a region",IF(TODAY()>$D19,"OVERDUE: register now",IF(TODAY()>=$C19,"Open: register by "&TEXT($D19,"dd/mm/yyyy"),"Opens "&TEXT($C19,"dd/mm/yyyy")))))) | AF19: =IF(ISNUMBER($AD19),EDATE($AD19,12)-1,"") | AH19: =IF(ISNUMBER($AG19),$AG19+27,"") | AJ19: =IF(AND($A19<>"",ISNUMBER($D19),NOT(ISNUMBER($AD19))),$D19,"")
C20: =IF($B20="","",IFERROR(VLOOKUP($B20,$A$112:$C$120,2,FALSE),"")) | D20: =IF($B20="","",IFERROR(VLOOKUP($B20,$A$112:$C$120,3,FALSE),"")) | E20: =IF(OR($D20="",ISNUMBER($AD20)),"",$D20-TODAY()) | F20: =IF($A20="","",COUNTIF($K20:$T20,"Yes")+COUNTIF($K20:$T20,"N/A")+IF(OR($U20="N/A",AND($U20="Yes",ISNUMBER($V20))),1,0)+IF(OR($W20="N/A",AND($W20="Yes",ISNUMBER($X20))),1,0)+COUNTIF($Y20:$AC20,"Yes")+COUNTIF($Y20:$AC20,"N/A")) | G20: =IF($A20="","",17-$F20) | H20: =IF($A20="","",$F20/17) | I20: =IF($A20="","",IF(ISNUMBER($AD20),"Registered",IF($G20=0,"Ready",IF($G20<=3,"Nearly","Not ready")))) | J20: =IF($A20="","",IF(ISNUMBER($AD20),"Registered",IF($D20="","Pick a region",IF(TODAY()>$D20,"OVERDUE: register now",IF(TODAY()>=$C20,"Open: register by "&TEXT($D20,"dd/mm/yyyy"),"Opens "&TEXT($C20,"dd/mm/yyyy")))))) | AF20: =IF(ISNUMBER($AD20),EDATE($AD20,12)-1,"") | AH20: =IF(ISNUMBER($AG20),$AG20+27,"") | AJ20: =IF(AND($A20<>"",ISNUMBER($D20),NOT(ISNUMBER($AD20))),$D20,"")
C21: =IF($B21="","",IFERROR(VLOOKUP($B21,$A$112:$C$120,2,FALSE),"")) | D21: =IF($B21="","",IFERROR(VLOOKUP($B21,$A$112:$C$120,3,FALSE),"")) | E21: =IF(OR($D21="",ISNUMBER($AD21)),"",$D21-TODAY()) | F21: =IF($A21="","",COUNTIF($K21:$T21,"Yes")+COUNTIF($K21:$T21,"N/A")+IF(OR($U21="N/A",AND($U21="Yes",ISNUMBER($V21))),1,0)+IF(OR($W21="N/A",AND($W21="Yes",ISNUMBER($X21))),1,0)+COUNTIF($Y21:$AC21,"Yes")+COUNTIF($Y21:$AC21,"N/A")) | G21: =IF($A21="","",17-$F21) | H21: =IF($A21="","",$F21/17) | I21: =IF($A21="","",IF(ISNUMBER($AD21),"Registered",IF($G21=0,"Ready",IF($G21<=3,"Nearly","Not ready")))) | J21: =IF($A21="","",IF(ISNUMBER($AD21),"Registered",IF($D21="","Pick a region",IF(TODAY()>$D21,"OVERDUE: register now",IF(TODAY()>=$C21,"Open: register by "&TEXT($D21,"dd/mm/yyyy"),"Opens "&TEXT($C21,"dd/mm/yyyy")))))) | AF21: =IF(ISNUMBER($AD21),EDATE($AD21,12)-1,"") | AH21: =IF(ISNUMBER($AG21),$AG21+27,"") | AJ21: =IF(AND($A21<>"",ISNUMBER($D21),NOT(ISNUMBER($AD21))),$D21,"")
C22: =IF($B22="","",IFERROR(VLOOKUP($B22,$A$112:$C$120,2,FALSE),"")) | D22: =IF($B22="","",IFERROR(VLOOKUP($B22,$A$112:$C$120,3,FALSE),"")) | E22: =IF(OR($D22="",ISNUMBER($AD22)),"",$D22-TODAY()) | F22: =IF($A22="","",COUNTIF($K22:$T22,"Yes")+COUNTIF($K22:$T22,"N/A")+IF(OR($U22="N/A",AND($U22="Yes",ISNUMBER($V22))),1,0)+IF(OR($W22="N/A",AND($W22="Yes",ISNUMBER($X22))),1,0)+COUNTIF($Y22:$AC22,"Yes")+COUNTIF($Y22:$AC22,"N/A")) | G22: =IF($A22="","",17-$F22) | H22: =IF($A22="","",$F22/17) | I22: =IF($A22="","",IF(ISNUMBER($AD22),"Registered",IF($G22=0,"Ready",IF($G22<=3,"Nearly","Not ready")))) | J22: =IF($A22="","",IF(ISNUMBER($AD22),"Registered",IF($D22="","Pick a region",IF(TODAY()>$D22,"OVERDUE: register now",IF(TODAY()>=$C22,"Open: register by "&TEXT($D22,"dd/mm/yyyy"),"Opens "&TEXT($C22,"dd/mm/yyyy")))))) | AF22: =IF(ISNUMBER($AD22),EDATE($AD22,12)-1,"") | AH22: =IF(ISNUMBER($AG22),$AG22+27,"") | AJ22: =IF(AND($A22<>"",ISNUMBER($D22),NOT(ISNUMBER($AD22))),$D22,"")
... C108: =IF($B108="","",IFERROR(VLOOKUP($B108,$A$112:$C$120,2,FALSE),"")) | D108: =IF($B108="","",IFERROR(VLOOKUP($B108,$A$112:$C$120,3,FALSE),"")) | E108: =IF(OR($D108="",ISNUMBER($AD108)),"",$D108-TODAY()) | F108: =IF($A108="","",COUNTIF($K108:$T108,"Yes")+COUNTIF($K108:$T108,"N/A")+IF(OR($U108="N/A",AND($U108="Yes",ISNUMBER($V108))),1,0)+IF(OR($W108="N/A",AND($W108="Yes",ISNUMBER($X108))),1,0)+COUNTIF($Y108:$AC108,"Yes")+COUNTIF($Y108:$AC108,"N/A")) | G108: =IF($A108="","",17-$F108) | H108: =IF($A108="","",$F108/17) | I108: =IF($A108="","",IF(ISNUMBER($AD108),"Registered",IF($G108=0,"Ready",IF($G108<=3,"Nearly","Not ready")))) | J108: =IF($A108="","",IF(ISNUMBER($AD108),"Registered",IF($D108="","Pick a region",IF(TODAY()>$D108,"OVERDUE: register now",IF(TODAY()>=$C108,"Open: register by "&TEXT($D108,"dd/mm/yyyy"),"Opens "&TEXT($C108,"dd/mm/yyyy")))))) | AF108: =IF(ISNUMBER($AD108),EDATE($AD108,12)-1,"") | AH108: =IF(ISNUMBER($AG108),$AG108+27,"") | AJ108: =IF(AND($A108<>"",ISNUMBER($D108),NOT(ISNUMBER($AD108))),$D108,"")
A110: REGIONAL ROLLOUT (draft regulations, reg 1): edit the dates here if the final regulations change them
A111: Region | B111: Registration opens | C111: Register by (opens + 3 months) | D111: Source
A112: West Midlands | B112: 46371 | C112: =EDATE($B112,3)-1 -> 46460 | D112: Draft Private Rented Sector Database Regulations 2026, reg 1(3) and Schedule 1 (list of councils in each region)
A113: East of England | B113: 46402 | C113: =EDATE($B113,3)-1 -> 46491 | D113: Draft Private Rented Sector Database Regulations 2026, reg 1(3) and Schedule 1 (list of councils in each region)
A114: East Midlands | B114: 46433 | C114: =EDATE($B114,3)-1 -> 46521 | D114: Draft Private Rented Sector Database Regulations 2026, reg 1(3) and Schedule 1 (list of councils in each region)
A115: South East | B115: 46461 | C115: =EDATE($B115,3)-1 -> 46552 | D115: Draft Private Rented Sector Database Regulations 2026, reg 1(3) and Schedule 1 (list of councils in each region)
A116: Yorkshire and Humber | B116: 46492 | C116: =EDATE($B116,3)-1 -> 46582 | D116: Draft Private Rented Sector Database Regulations 2026, reg 1(3) and Schedule 1 (list of councils in each region)
A117: North West | B117: 46522 | C117: =EDATE($B117,3)-1 -> 46613 | D117: Draft Private Rented Sector Database Regulations 2026, reg 1(3) and Schedule 1 (list of councils in each region)
A118: North East | B118: 46553 | C118: =EDATE($B118,3)-1 -> 46644 | D118: Draft Private Rented Sector Database Regulations 2026, reg 1(3) and Schedule 1 (list of councils in each region)
A119: London | B119: 46583 | C119: =EDATE($B119,3)-1 -> 46674 | D119: Draft Private Rented Sector Database Regulations 2026, reg 1(3) and Schedule 1 (list of councils in each region)
A120: South West | B120: 46614 | C120: =EDATE($B120,3)-1 -> 46705 | D120: Draft Private Rented Sector Database Regulations 2026, reg 1(3) and Schedule 1 (list of councils in each region)
A121: Register-by is the opening date plus three months, less a day (GOV.UK, 9 September 2026: a three-month period once your area is called; all landlords actively letting must be registered by 14 November 2027). Anything that becomes out of date must be updated within 28 days (the tracker counts the 28-day period as beginning on the day of the change). Entries renew every 12 months.
A122: Official draft regulations: legislation.gov.uk/ukdsi/2026/9780348286861
A123: LANDLORD ENTRY CHECKLIST (draft Schedule 2): one landlord entry covers all the properties you let
A124: Information and documents needed | I124: Ready? | J124: Notes
A125: Individual landlord: name, date of birth, residential address, telephone number and email address.
A126: Organisation: name, type of legal entity, address (not a PO box), telephone number and email address.
...

Sheet Properties
A1: =IF(TRIM('Start Here'!$C$20)="","HMO Compliance Tracker 2026",TRIM('Start Here'!$C$20))&IF(TRIM('Start Here'!$C$21)="",""," | "&TRIM('Start Here'!$C$21))&IF(TRIM('Start Here'!$C$22)="",""," | "&TRIM('Start Here'!$C$22))&IF(TRIM('Start Here'!$C$23)="",""," | "&TRIM('Start Here'!$C$23)) -> HMO Compliance Tracker 2026
A2: Properties
A3: One row per property. The property name in column A must be unique: it feeds the dropdowns on the other sheets. Grey columns are automatic. Rows marked SAMPLE show how it works: clear their white cells and add your own.
A5: Property (address) - must be unique | B5: Council / local authority | C5: Licence type | D5: Licence number | E5: Licence start | F5: Licence expiry | G5: Licence days left (auto) | H5: Licence status (auto) | I5: Max permitted occupants | J5: Current occupants | K5: Over-occupied? (auto) | L5: Storeys | M5: Rooms | N5: EPC rating | O5: EPC expiry | P5: EPC status (auto) | Q5: PRS Database registration ref (new for 2026; auto from PRS Database Readiness) | R5: Manager name | S5: Manager phone | T5: Notes
A6: SAMPLE - 12 Acacia Road, Exampleton | B6: Exampleton Borough Council | C6: Mandatory HMO | D6: SAMPLE-0001 | E6: =TODAY()-(1700) -> 44597 | F6: =TODAY()+(126) -> 46423 | G6: =IF(OR($C6="",NOT(ISNUMBER($F6))),"",$F6-TODAY()) -> 126 | H6: =IF($C6="","",IF($C6="Not licensable","n/a",IF($C6="Applied-pending","Pending",IF(NOT(ISNUMBER($F6)),"No date",IF($G6<0,"Expired",IF($G6<=30,"Expires <=30",IF($G6<=60,"Expires 31-60","Valid"))))))) -> Valid | I6: 5 | J6: 6 | K6: =IF(OR(NOT(ISNUMBER($I6)),NOT(ISNUMBER($J6))),"",IF($J6>$I6,"OVER","OK")) -> OVER | L6: 3 | M6: 5 | N6: D | O6: =TODAY()-(1500) -> 44797 | P6: =IF($N6="","",IF(OR($N6="F",$N6="G"),"Below E - check",IF(NOT(ISNUMBER($O6)),"No date",IF($O6<TODAY(),"Expired",IF($O6-TODAY()<=60,"Expires <=60","Valid"))))) -> Expired | Q6: =IF($A6="","",IFERROR(IF(INDEX('PRS Database Readiness'!$AE$9:$AE$108,MATCH($A6,'PRS Database Readiness'!$A$9:$A$108,0))="","",INDEX('PRS Database Readiness'!$AE$9:$AE$108,MATCH($A6,'PRS Database Readiness'!$A$9:$A$108,0))),"")) | R6: A. Manager | S6: 01234 567890 | T6: SAMPLE ROW - delete the white cells in this row. (6 occupants vs 5 permitted shows the over-occupied flag.)
A7: SAMPLE - Flat 3, 8 Demo Street, Sampleford | B7: Sampleford City Council | C7: Additional | D7: SAMPLE-0002 | E7: =TODAY()-(900) -> 45397 | F7: =TODAY()+(40) -> 46337 | G7: =IF(OR($C7="",NOT(ISNUMBER($F7))),"",$F7-TODAY()) -> 40 | H7: =IF($C7="","",IF($C7="Not licensable","n/a",IF($C7="Applied-pending","Pending",IF(NOT(ISNUMBER($F7)),"No date",IF($G7<0,"Expired",IF($G7<=30,"Expires <=30",IF($G7<=60,"Expires 31-60","Valid"))))))) -> Expires 31-60 | I7: 4 | J7: 4 | K7: =IF(OR(NOT(ISNUMBER($I7)),NOT(ISNUMBER($J7))),"",IF($J7>$I7,"OVER","OK")) -> OK | L7: 2 | M7: 4 | N7: C | O7: =TODAY()-(2000) -> 44297 | P7: =IF($N7="","",IF(OR($N7="F",$N7="G"),"Below E - check",IF(NOT(ISNUMBER($O7)),"No date",IF($O7<TODAY(),"Expired",IF($O7-TODAY()<=60,"Expires <=60","Valid"))))) -> Expired | Q7: =IF($A7="","",IFERROR(IF(INDEX('PRS Database Readiness'!$AE$9:$AE$108,MATCH($A7,'PRS Database Readiness'!$A$9:$A$108,0))="","",INDEX('PRS Database Readiness'!$AE$9:$AE$108,MATCH($A7,'PRS Database Readiness'!$A$9:$A$108,0))),"")) | R7: A. Manager | S7: 01234 567890 | T7: SAMPLE ROW - delete the white cells in this row.
G8: =IF(OR($C8="",NOT(ISNUMBER($F8))),"",$F8-TODAY()) | H8: =IF($C8="","",IF($C8="Not licensable","n/a",IF($C8="Applied-pending","Pending",IF(NOT(ISNUMBER($F8)),"No date",IF($G8<0,"Expired",IF($G8<=30,"Expires <=30",IF($G8<=60,"Expires 31-60","Valid"))))))) | K8: =IF(OR(NOT(ISNUMBER($I8)),NOT(ISNUMBER($J8))),"",IF($J8>$I8,"OVER","OK")) | P8: =IF($N8="","",IF(OR($N8="F",$N8="G"),"Below E - check",IF(NOT(ISNUMBER($O8)),"No date",IF($O8<TODAY(),"Expired",IF($O8-TODAY()<=60,"Expires <=60","Valid"))))) | Q8: =IF($A8="","",IFERROR(IF(INDEX('PRS Database Readiness'!$AE$9:$AE$108,MATCH($A8,'PRS Database Readiness'!$A$9:$A$108,0))="","",INDEX('PRS Database Readiness'!$AE$9:$AE$108,MATCH($A8,'PRS Database Readiness'!$A$9:$A$108,0))),""))
G9: =IF(OR($C9="",NOT(ISNUMBER($F9))),"",$F9-TODAY()) | H9: =IF($C9="","",IF($C9="Not licensable","n/a",IF($C9="Applied-pending","Pending",IF(NOT(ISNUMBER($F9)),"No date",IF($G9<0,"Expired",IF($G9<=30,"Expires <=30",IF($G9<=60,"Expires 31-60","Valid"))))))) | K9: =IF(OR(NOT(ISNUMBER($I9)),NOT(ISNUMBER($J9))),"",IF($J9>$I9,"OVER","OK")) | P9: =IF($N9="","",IF(OR($N9="F",$N9="G"),"Below E - check",IF(NOT(ISNUMBER($O9)),"No date",IF($O9<TODAY(),"Expired",IF($O9-TODAY()<=60,"Expires <=60","Valid"))))) | Q9: =IF($A9="","",IFERROR(IF(INDEX('PRS Database Readiness'!$AE$9:$AE$108,MATCH($A9,'PRS Database Readiness'!$A$9:$A$108,0))="","",INDEX('PRS Database Readiness'!$AE$9:$AE$108,MATCH($A9,'PRS Database Readiness'!$A$9:$A$108,0))),""))
G10: =IF(OR($C10="",NOT(ISNUMBER($F10))),"",$F10-TODAY()) | H10: =IF($C10="","",IF($C10="Not licensable","n/a",IF($C10="Applied-pending","Pending",IF(NOT(ISNUMBER($F10)),"No date",IF($G10<0,"Expired",IF($G10<=30,"Expires <=30",IF($G10<=60,"Expires 31-60","Valid"))))))) | K10: =IF(OR(NOT(ISNUMBER($I10)),NOT(ISNUMBER($J10))),"",IF($J10>$I10,"OVER","OK")) | P10: =IF($N10="","",IF(OR($N10="F",$N10="G"),"Below E - check",IF(NOT(ISNUMBER($O10)),"No date",IF($O10<TODAY(),"Expired",IF($O10-TODAY()<=60,"Expires <=60","Valid"))))) | Q10: =IF($A10="","",IFERROR(IF(INDEX('PRS Database Readiness'!$AE$9:$AE$108,MATCH($A10,'PRS Database Readiness'!$A$9:$A$108,0))="","",INDEX('PRS Database Readiness'!$AE$9:$AE$108,MATCH($A10,'PRS Database Readiness'!$A$9:$A$108,0))),""))
G11: =IF(OR($C11="",NOT(ISNUMBER($F11))),"",$F11-TODAY()) | H11: =IF($C11="","",IF($C11="Not licensable","n/a",IF($C11="Applied-pending","Pending",IF(NOT(ISNUMBER($F11)),"No date",IF($G11<0,"Expired",IF($G11<=30,"Expires <=30",IF($G11<=60,"Expires 31-60","Valid"))))))) | K11: =IF(OR(NOT(ISNUMBER($I11)),NOT(ISNUMBER($J11))),"",IF($J11>$I11,"OVER","OK")) | P11: =IF($N11="","",IF(OR($N11="F",$N11="G"),"Below E - check",IF(NOT(ISNUMBER($O11)),"No date",IF($O11<TODAY(),"Expired",IF($O11-TODAY()<=60,"Expires <=60","Valid"))))) | Q11: =IF($A11="","",IFERROR(IF(INDEX('PRS Database Readiness'!$AE$9:$AE$108,MATCH($A11,'PRS Database Readiness'!$A$9:$A$108,0))="","",INDEX('PRS Database Readiness'!$AE$9:$AE$108,MATCH($A11,'PRS Database Readiness'!$A$9:$A$108,0))),""))
G12: =IF(OR($C12="",NOT(ISNUMBER($F12))),"",$F12-TODAY()) | H12: =IF($C12="","",IF($C12="Not licensable","n/a",IF($C12="Applied-pending","Pending",IF(NOT(ISNUMBER($F12)),"No date",IF($G12<0,"Expired",IF($G12<=30,"Expires <=30",IF($G12<=60,"Expires 31-60","Valid"))))))) | K12: =IF(OR(NOT(ISNUMBER($I12)),NOT(ISNUMBER($J12))),"",IF($J12>$I12,"OVER","OK")) | P12: =IF($N12="","",IF(OR($N12="F",$N12="G"),"Below E - check",IF(NOT(ISNUMBER($O12)),"No date",IF($O12<TODAY(),"Expired",IF($O12-TODAY()<=60,"Expires <=60","Valid"))))) | Q12: =IF($A12="","",IFERROR(IF(INDEX('PRS Database Readiness'!$AE$9:$AE$108,MATCH($A12,'PRS Database Readiness'!$A$9:$A$108,0))="","",INDEX('PRS Database Readiness'!$AE$9:$AE$108,MATCH($A12,'PRS Database Readiness'!$A$9:$A$108,0))),""))
G13: =IF(OR($C13="",NOT(ISNUMBER($F13))),"",$F13-TODAY()) | H13: =IF($C13="","",IF($C13="Not licensable","n/a",IF($C13="Applied-pending","Pending",IF(NOT(ISNUMBER($F13)),"No date",IF($G13<0,"Expired",IF($G13<=30,"Expires <=30",IF($G13<=60,"Expires 31-60","Valid"))))))) | K13: =IF(OR(NOT(ISNUMBER($I13)),NOT(ISNUMBER($J13))),"",IF($J13>$I13,"OVER","OK")) | P13: =IF($N13="","",IF(OR($N13="F",$N13="G"),"Below E - check",IF(NOT(ISNUMBER($O13)),"No date",IF($O13<TODAY(),"Expired",IF($O13-TODAY()<=60,"Expires <=60","Valid"))))) | Q13: =IF($A13="","",IFERROR(IF(INDEX('PRS Database Readiness'!$AE$9:$AE$108,MATCH($A13,'PRS Database Readiness'!$A$9:$A$108,0))="","",INDEX('PRS Database Readiness'!$AE$9:$AE$108,MATCH($A13,'PRS Database Readiness'!$A$9:$A$108,0))),""))
G14: =IF(OR($C14="",NOT(ISNUMBER($F14))),"",$F14-TODAY()) | H14: =IF($C14="","",IF($C14="Not licensable","n/a",IF($C14="Applied-pending","Pending",IF(NOT(ISNUMBER($F14)),"No date",IF($G14<0,"Expired",IF($G14<=30,"Expires <=30",IF($G14<=60,"Expires 31-60","Valid"))))))) | K14: =IF(OR(NOT(ISNUMBER($I14)),NOT(ISNUMBER($J14))),"",IF($J14>$I14,"OVER","OK")) | P14: =IF($N14="","",IF(OR($N14="F",$N14="G"),"Below E - check",IF(NOT(ISNUMBER($O14)),"No date",IF($O14<TODAY(),"Expired",IF($O14-TODAY()<=60,"Expires <=60","Valid"))))) | Q14: =IF($A14="","",IFERROR(IF(INDEX('PRS Database Readiness'!$AE$9:$AE$108,MATCH($A14,'PRS Database Readiness'!$A$9:$A$108,0))="","",INDEX('PRS Database Readiness'!$AE$9:$AE$108,MATCH($A14,'PRS Database Readiness'!$A$9:$A$108,0))),""))
G15: =IF(OR($C15="",NOT(ISNUMBER($F15))),"",$F15-TODAY()) | H15: =IF($C15="","",IF($C15="Not licensable","n/a",IF($C15="Applied-pending","Pending",IF(NOT(ISNUMBER($F15)),"No date",IF($G15<0,"Expired",IF($G15<=30,"Expires <=30",IF($G15<=60,"Expires 31-60","Valid"))))))) | K15: =IF(OR(NOT(ISNUMBER($I15)),NOT(ISNUMBER($J15))),"",IF($J15>$I15,"OVER","OK")) | P15: =IF($N15="","",IF(OR($N15="F",$N15="G"),"Below E - check",IF(NOT(ISNUMBER($O15)),"No date",IF($O15<TODAY(),"Expired",IF($O15-TODAY()<=60,"Expires <=60","Valid"))))) | Q15: =IF($A15="","",IFERROR(IF(INDEX('PRS Database Readiness'!$AE$9:$AE$108,MATCH($A15,'PRS Database Readiness'!$A$9:$A$108,0))="","",INDEX('PRS Database Readiness'!$AE$9:$AE$108,MATCH($A15,'PRS Database Readiness'!$A$9:$A$108,0))),""))
G16: =IF(OR($C16="",NOT(ISNUMBER($F16))),"",$F16-TODAY()) | H16: =IF($C16="","",IF($C16="Not licensable","n/a",IF($C16="Applied-pending","Pending",IF(NOT(ISNUMBER($F16)),"No date",IF($G16<0,"Expired",IF($G16<=30,"Expires <=30",IF($G16<=60,"Expires 31-60","Valid"))))))) | K16: =IF(OR(NOT(ISNUMBER($I16)),NOT(ISNUMBER($J16))),"",IF($J16>$I16,"OVER","OK")) | P16: =IF($N16="","",IF(OR($N16="F",$N16="G"),"Below E - check",IF(NOT(ISNUMBER($O16)),"No date",IF($O16<TODAY(),"Expired",IF($O16-TODAY()<=60,"Expires <=60","Valid"))))) | Q16: =IF($A16="","",IFERROR(IF(INDEX('PRS Database Readiness'!$AE$9:$AE$108,MATCH($A16,'PRS Database Readiness'!$A$9:$A$108,0))="","",INDEX('PRS Database Readiness'!$AE$9:$AE$108,MATCH($A16,'PRS Database Readiness'!$A$9:$A$108,0))),""))
G17: =IF(OR($C17="",NOT(ISNUMBER($F17))),"",$F17-TODAY()) | H17: =IF($C17="","",IF($C17="Not licensable","n/a",IF($C17="Applied-pending","Pending",IF(NOT(ISNUMBER($F17)),"No date",IF($G17<0,"Expired",IF($G17<=30,"Expires <=30",IF($G17<=60,"Expires 31-60","Valid"))))))) | K17: =IF(OR(NOT(ISNUMBER($I17)),NOT(ISNUMBER($J17))),"",IF($J17>$I17,"OVER","OK")) | P17: =IF($N17="","",IF(OR($N17="F",$N17="G"),"Below E - check",IF(NOT(ISNUMBER($O17)),"No date",IF($O17<TODAY(),"Expired",IF($O17-TODAY()<=60,"Expires <=60","Valid"))))) | Q17: =IF($A17="","",IFERROR(IF(INDEX('PRS Database Readiness'!$AE$9:$AE$108,MATCH($A17,'PRS Database Readiness'!$A$9:$A$108,0))="","",INDEX('PRS Database Readiness'!$AE$9:$AE$108,MATCH($A17,'PRS Database Readiness'!$A$9:$A$108,0))),""))
G18: =IF(OR($C18="",NOT(ISNUMBER($F18))),"",$F18-TODAY()) | H18: =IF($C18="","",IF($C18="Not licensable","n/a",IF($C18="Applied-pending","Pending",IF(NOT(ISNUMBER($F18)),"No date",IF($G18<0,"Expired",IF($G18<=30,"Expires <=30",IF($G18<=60,"Expires 31-60","Valid"))))))) | K18: =IF(OR(NOT(ISNUMBER($I18)),NOT(ISNUMBER($J18))),"",IF($J18>$I18,"OVER","OK")) | P18: =IF($N18="","",IF(OR($N18="F",$N18="G"),"Below E - check",IF(NOT(ISNUMBER($O18)),"No date",IF($O18<TODAY(),"Expired",IF($O18-TODAY()<=60,"Expires <=60","Valid"))))) | Q18: =IF($A18="","",IFERROR(IF(INDEX('PRS Database Readiness'!$AE$9:$AE$108,MATCH($A18,'PRS Database Readiness'!$A$9:$A$108,0))="","",INDEX('PRS Database Readiness'!$AE$9:$AE$108,MATCH($A18,'PRS Database Readiness'!$A$9:$A$108,0))),""))
G19: =IF(OR($C19="",NOT(ISNUMBER($F19))),"",$F19-TODAY()) | H19: =IF($C19="","",IF($C19="Not licensable","n/a",IF($C19="Applied-pending","Pending",IF(NOT(ISNUMBER($F19)),"No date",IF($G19<0,"Expired",IF($G19<=30,"Expires <=30",IF($G19<=60,"Expires 31-60","Valid"))))))) | K19: =IF(OR(NOT(ISNUMBER($I19)),NOT(ISNUMBER($J19))),"",IF($J19>$I19,"OVER","OK")) | P19: =IF($N19="","",IF(OR($N19="F",$N19="G"),"Below E - check",IF(NOT(ISNUMBER($O19)),"No date",IF($O19<TODAY(),"Expired",IF($O19-TODAY()<=60,"Expires <=60","Valid"))))) | Q19: =IF($A19="","",IFERROR(IF(INDEX('PRS Database Readiness'!$AE$9:$AE$108,MATCH($A19,'PRS Database Readiness'!$A$9:$A$108,0))="","",INDEX('PRS Database Readiness'!$AE$9:$AE$108,MATCH($A19,'PRS Database Readiness'!$A$9:$A$108,0))),""))
